<sdf version='1.7'>
  <world name='default'>
    <light name='sun' type='directional'>
      <cast_shadows>1</cast_shadows>
      <pose>0 0 10 0 -0 0</pose>
      <diffuse>0.8 0.8 0.8 1</diffuse>
      <specular>0.2 0.2 0.2 1</specular>
      <attenuation>
        <range>1000</range>
        <constant>0.9</constant>
        <linear>0.01</linear>
        <quadratic>0.001</quadratic>
      </attenuation>
      <direction>-0.5 0.1 -0.9</direction>
      <spot>
        <inner_angle>0</inner_angle>
        <outer_angle>0</outer_angle>
        <falloff>0</falloff>
      </spot>
    </light>
    <model name='ground_plane'>
      <static>1</static>
      <link name='link'>
        <collision name='collision'>
          <geometry>
            <plane>
              <normal>0 0 1</normal>
              <size>100 100</size>
            </plane>
          </geometry>
          <surface>
            <friction>
              <ode>
                <mu>100</mu>
                <mu2>50</mu2>
              </ode>
              <torsional>
                <ode/>
              </torsional>
            </friction>
            <contact>
              <ode/>
            </contact>
            <bounce/>
          </surface>
          <max_contacts>10</max_contacts>
        </collision>
        <visual name='visual'>
          <cast_shadows>0</cast_shadows>
          <geometry>
            <plane>
              <normal>0 0 1</normal>
              <size>100 100</size>
            </plane>
          </geometry>
          <material>
            <script>
              <uri>file://media/materials/scripts/gazebo.material</uri>
              <name>Gazebo/Grey</name>
            </script>
          </material>
        </visual>
        <self_collide>0</self_collide>
        <enable_wind>0</enable_wind>
        <kinematic>0</kinematic>
      </link>
    </model>
    <gravity>0 0 -9.8</gravity>
    <magnetic_field>6e-06 2.3e-05 -4.2e-05</magnetic_field>
    <atmosphere type='adiabatic'/>
    <physics type='ode'>
      <max_step_size>0.001</max_step_size>
      <real_time_factor>1</real_time_factor>
      <real_time_update_rate>1000</real_time_update_rate>
    </physics>
    <scene>
      <ambient>0.4 0.4 0.4 1</ambient>
      <background>0.7 0.7 0.7 1</background>
      <shadows>1</shadows>
    </scene>
    <audio>
      <device>default</device>
    </audio>
    <wind/>
    <spherical_coordinates>
      <surface_model>EARTH_WGS84</surface_model>
      <latitude_deg>0</latitude_deg>
      <longitude_deg>0</longitude_deg>
      <elevation>0</elevation>
      <heading_deg>0</heading_deg>
    </spherical_coordinates>
    <model name='room'>
      <pose>-2.7432 0.559554 0 0 -0 0</pose>
      <link name='Wall_10'>
        <collision name='Wall_10_Collision'>
          <geometry>
            <box>
              <size>4 0.15 1</size>
            </box>
          </geometry>
          <pose>0 0 0.5 0 -0 0</pose>
          <max_contacts>10</max_contacts>
          <surface>
            <contact>
              <ode/>
            </contact>
            <bounce/>
            <friction>
              <torsional>
                <ode/>
              </torsional>
              <ode/>
            </friction>
          </surface>
        </collision>
        <visual name='Wall_10_Visual'>
          <pose>0 0 0.5 0 -0 0</pose>
          <geometry>
            <box>
              <size>4 0.15 1</size>
            </box>
          </geometry>
          <material>
            <script>
              <uri>file://media/materials/scripts/gazebo.material</uri>
              <name>Gazebo/Grey</name>
            </script>
            <ambient>1 1 1 1</ambient>
          </material>
          <meta>
            <layer>0</layer>
          </meta>
        </visual>
        <pose>3.525 0.004783 0 0 -0 -1.5708</pose>
        <self_collide>0</self_collide>
        <enable_wind>0</enable_wind>
        <kinematic>0</kinematic>
      </link>
      <link name='Wall_12'>
        <collision name='Wall_12_Collision'>
          <geometry>
            <box>
              <size>7.2 0.15 1</size>
            </box>
          </geometry>
          <pose>0 0 0.5 0 -0 0</pose>
          <max_contacts>10</max_contacts>
          <surface>
            <contact>
              <ode/>
            </contact>
            <bounce/>
            <friction>
              <torsional>
                <ode/>
              </torsional>
              <ode/>
            </friction>
          </surface>
        </collision>
        <visual name='Wall_12_Visual'>
          <pose>0 0 0.5 0 -0 0</pose>
          <geometry>
            <box>
              <size>7.2 0.15 1</size>
            </box>
          </geometry>
          <material>
            <script>
              <uri>file://media/materials/scripts/gazebo.material</uri>
              <name>Gazebo/Grey</name>
            </script>
            <ambient>1 1 1 1</ambient>
          </material>
          <meta>
            <layer>0</layer>
          </meta>
        </visual>
        <pose>-2e-06 -1.925 0 0 -0 -3.14024</pose>
        <self_collide>0</self_collide>
        <enable_wind>0</enable_wind>
        <kinematic>0</kinematic>
      </link>
      <link name='Wall_14'>
        <collision name='Wall_14_Collision'>
          <geometry>
            <box>
              <size>4 0.15 1</size>
            </box>
          </geometry>
          <pose>0 0 0.5 0 -0 0</pose>
          <max_contacts>10</max_contacts>
          <surface>
            <contact>
              <ode/>
            </contact>
            <bounce/>
            <friction>
              <torsional>
                <ode/>
              </torsional>
              <ode/>
            </friction>
          </surface>
        </collision>
        <visual name='Wall_14_Visual'>
          <pose>0 0 0.5 0 -0 0</pose>
          <geometry>
            <box>
              <size>4 0.15 1</size>
            </box>
          </geometry>
          <material>
            <script>
              <uri>file://media/materials/scripts/gazebo.material</uri>
              <name>Gazebo/Grey</name>
            </script>
            <ambient>1 1 1 1</ambient>
          </material>
          <meta>
            <layer>0</layer>
          </meta>
        </visual>
        <pose>-3.525 -0.004783 0 0 -0 -1.5708</pose>
        <self_collide>0</self_collide>
        <enable_wind>0</enable_wind>
        <kinematic>0</kinematic>
      </link>
      <link name='Wall_16'>
        <collision name='Wall_16_Collision'>
          <geometry>
            <box>
              <size>3.2 0.15 1</size>
            </box>
          </geometry>
          <pose>0 0 0.5 0 -0 0</pose>
          <max_contacts>10</max_contacts>
          <surface>
            <contact>
              <ode/>
            </contact>
            <bounce/>
            <friction>
              <torsional>
                <ode/>
              </torsional>
              <ode/>
            </friction>
          </surface>
        </collision>
        <visual name='Wall_16_Visual'>
          <pose>0 0 0.5 0 -0 0</pose>
          <geometry>
            <box>
              <size>3.2 0.15 1</size>
            </box>
          </geometry>
          <material>
            <script>
              <uri>file://media/materials/scripts/gazebo.material</uri>
              <name>Gazebo/Grey</name>
            </script>
            <ambient>1 1 1 1</ambient>
          </material>
          <meta>
            <layer>0</layer>
          </meta>
        </visual>
        <pose>-0.9398 0.583447 0 0 -0 0</pose>
        <self_collide>0</self_collide>
        <enable_wind>0</enable_wind>
        <kinematic>0</kinematic>
      </link>
      <link name='Wall_18'>
        <collision name='Wall_18_Collision'>
          <geometry>
            <box>
              <size>1 0.15 1</size>
            </box>
          </geometry>
          <pose>0 0 0.5 0 -0 0</pose>
          <max_contacts>10</max_contacts>
          <surface>
            <contact>
              <ode/>
            </contact>
            <bounce/>
            <friction>
              <torsional>
                <ode/>
              </torsional>
              <ode/>
            </friction>
          </surface>
        </collision>
        <visual name='Wall_18_Visual'>
          <pose>0 0 0.5 0 -0 0</pose>
          <geometry>
            <box>
              <size>1 0.15 1</size>
            </box>
          </geometry>
          <material>
            <script>
              <uri>file://media/materials/scripts/gazebo.material</uri>
              <name>Gazebo/Grey</name>
            </script>
            <ambient>1 1 1 1</ambient>
          </material>
          <meta>
            <layer>0</layer>
          </meta>
        </visual>
        <pose>-2.4648 0.158446 0 0 -0 -1.5708</pose>
        <self_collide>0</self_collide>
        <enable_wind>0</enable_wind>
        <kinematic>0</kinematic>
      </link>
      <link name='Wall_19'>
        <collision name='Wall_19_Collision'>
          <geometry>
            <box>
              <size>3.2 0.15 1</size>
            </box>
          </geometry>
          <pose>0 0 0.5 0 -0 0</pose>
          <max_contacts>10</max_contacts>
          <surface>
            <contact>
              <ode/>
            </contact>
            <bounce/>
            <friction>
              <torsional>
                <ode/>
              </torsional>
              <ode/>
            </friction>
          </surface>
        </collision>
        <visual name='Wall_19_Visual'>
          <pose>0 0 0.5 0 -0 0</pose>
          <geometry>
            <box>
              <size>3.2 0.15 1</size>
            </box>
          </geometry>
          <material>
            <script>
              <uri>file://media/materials/scripts/gazebo.material</uri>
              <name>Gazebo/Grey</name>
            </script>
            <ambient>1 1 1 1</ambient>
          </material>
          <meta>
            <layer>0</layer>
          </meta>
        </visual>
        <pose>-0.9398 -0.266553 0 0 -0 0</pose>
        <self_collide>0</self_collide>
        <enable_wind>0</enable_wind>
        <kinematic>0</kinematic>
      </link>
      <link name='Wall_21'>
        <collision name='Wall_21_Collision'>
          <geometry>
            <box>
              <size>1 0.15 1</size>
            </box>
          </geometry>
          <pose>0 0 0.5 0 -0 0</pose>
          <max_contacts>10</max_contacts>
          <surface>
            <contact>
              <ode/>
            </contact>
            <bounce/>
            <friction>
              <torsional>
                <ode/>
              </torsional>
              <ode/>
            </friction>
          </surface>
        </collision>
        <visual name='Wall_21_Visual'>
          <pose>0 0 0.5 0 -0 0</pose>
          <geometry>
            <box>
              <size>1 0.15 1</size>
            </box>
          </geometry>
          <material>
            <script>
              <uri>file://media/materials/scripts/gazebo.material</uri>
              <name>Gazebo/Grey</name>
            </script>
            <ambient>1 1 1 1</ambient>
          </material>
          <meta>
            <layer>0</layer>
          </meta>
        </visual>
        <pose>0.5852 0.158446 0 0 -0 -1.5708</pose>
        <self_collide>0</self_collide>
        <enable_wind>0</enable_wind>
        <kinematic>0</kinematic>
      </link>
      <link name='Wall_5'>
        <collision name='Wall_5_Collision'>
          <geometry>
            <box>
              <size>7.2 0.15 1</size>
            </box>
          </geometry>
          <pose>0 0 0.5 0 -0 0</pose>
          <max_contacts>10</max_contacts>
          <surface>
            <contact>
              <ode/>
            </contact>
            <bounce/>
            <friction>
              <torsional>
                <ode/>
              </torsional>
              <ode/>
            </friction>
          </surface>
        </collision>
        <visual name='Wall_5_Visual'>
          <pose>0 0 0.5 0 -0 0</pose>
          <geometry>
            <box>
              <size>7.2 0.15 1</size>
            </box>
          </geometry>
          <material>
            <script>
              <uri>file://media/materials/scripts/gazebo.material</uri>
              <name>Gazebo/Grey</name>
            </script>
            <ambient>1 1 1 1</ambient>
          </material>
          <meta>
            <layer>0</layer>
          </meta>
        </visual>
        <pose>1e-06 1.925 0 0 -0 0.001357</pose>
        <self_collide>0</self_collide>
        <enable_wind>0</enable_wind>
        <kinematic>0</kinematic>
      </link>
      <static>1</static>
    </model>
    <state world_name='default'>
      <sim_time>440 694000000</sim_time>
      <real_time>462 59224985</real_time>
      <wall_time>1778140430 196119795</wall_time>
      <iterations>440694</iterations>
      <model name='ground_plane'>
        <pose>0 0 0 0 -0 0</pose>
        <scale>1 1 1</scale>
        <link name='link'>
          <pose>0 0 0 0 -0 0</pose>
          <velocity>0 0 0 0 -0 0</velocity>
          <acceleration>0 0 0 0 -0 0</acceleration>
          <wrench>0 0 0 0 -0 0</wrench>
        </link>
      </model>
      <model name='room'>
        <pose>-2.91098 0.547766 0 0 -0 0</pose>
        <scale>1 1 1</scale>
        <link name='Wall_10'>
          <pose>0.614016 0.552549 0 0 0 -1.5708</pose>
          <velocity>0 0 0 0 -0 0</velocity>
          <acceleration>0 0 0 0 -0 0</acceleration>
          <wrench>0 0 0 0 -0 0</wrench>
        </link>
        <link name='Wall_12'>
          <pose>-2.91099 -1.37723 0 0 0 -3.14024</pose>
          <velocity>0 0 0 0 -0 0</velocity>
          <acceleration>0 0 0 0 -0 0</acceleration>
          <wrench>0 0 0 0 -0 0</wrench>
        </link>
        <link name='Wall_14'>
          <pose>-6.43598 0.542983 0 0 0 -1.5708</pose>
          <velocity>0 0 0 0 -0 0</velocity>
          <acceleration>0 0 0 0 -0 0</acceleration>
          <wrench>0 0 0 0 -0 0</wrench>
        </link>
        <link name='Wall_16'>
          <pose>-3.85078 1.13121 0 0 -0 0</pose>
          <velocity>0 0 0 0 -0 0</velocity>
          <acceleration>0 0 0 0 -0 0</acceleration>
          <wrench>0 0 0 0 -0 0</wrench>
        </link>
        <link name='Wall_18'>
          <pose>-5.37578 0.706212 0 0 0 -1.5708</pose>
          <velocity>0 0 0 0 -0 0</velocity>
          <acceleration>0 0 0 0 -0 0</acceleration>
          <wrench>0 0 0 0 -0 0</wrench>
        </link>
        <link name='Wall_19'>
          <pose>-3.85078 0.281213 0 0 -0 0</pose>
          <velocity>0 0 0 0 -0 0</velocity>
          <acceleration>0 0 0 0 -0 0</acceleration>
          <wrench>0 0 0 0 -0 0</wrench>
        </link>
        <link name='Wall_21'>
          <pose>-2.32578 0.706212 0 0 0 -1.5708</pose>
          <velocity>0 0 0 0 -0 0</velocity>
          <acceleration>0 0 0 0 -0 0</acceleration>
          <wrench>0 0 0 0 -0 0</wrench>
        </link>
        <link name='Wall_5'>
          <pose>-2.91098 2.47277 0 0 -0 0.001357</pose>
          <velocity>0 0 0 0 -0 0</velocity>
          <acceleration>0 0 0 0 -0 0</acceleration>
          <wrench>0 0 0 0 -0 0</wrench>
        </link>
      </model>
      <light name='sun'>
        <pose>0 0 10 0 -0 0</pose>
      </light>
    </state>
    <gui fullscreen='0'>
      <camera name='user_camera'>
        <pose>-12.5326 -13.2147 15.3889 0 0.959643 1.0682</pose>
        <view_controller>orbit</view_controller>
        <projection_type>perspective</projection_type>
      </camera>
    </gui>
    <model name='mm_robot'>
        <pose>0 0 0.05 0 0 3.14159265</pose>
        <link name='base_link'>
          <inertial>
            <pose>0.012562 0.006513 0.051993 0 -0 0</pose>
            <mass>103.722</mass>
            <inertia>
              <ixx>1.53012</ixx>
              <ixy>-0.000190794</ixy>
              <ixz>-0.0099034</ixz>
              <iyy>1.26252</iyy>
              <iyz>-4.25477e-05</iyz>
              <izz>50.0446</izz>
            </inertia>
          </inertial>
          <collision name='base_link_collision'>
            <pose>0 0 0 0 -0 0</pose>
            <geometry>
              <mesh>
                <scale>1 1 1</scale>
                <uri>file:///home/fishros/MobileManipulator/workplace/install/mm_description/share/mm_description/meshes/base_link.stl</uri>
              </mesh>
            </geometry>
          </collision>
          <collision name='base_link_fixed_joint_lump__Link_11_collision_1'>
            <pose>-0.179276 0.000111 0.0758 3.14159 -1.5708 0</pose>
            <geometry>
              <mesh>
                <scale>1 1 1</scale>
                <uri>file:///home/fishros/MobileManipulator/workplace/install/mm_description/share/mm_description/meshes/Link_11.stl</uri>
              </mesh>
            </geometry>
          </collision>
          <collision name='base_link_fixed_joint_lump__Link_12_collision_2'>
            <pose>0.105689 -1.3e-05 0.2208 -3.14159 -0 -4e-06</pose>
            <geometry>
              <mesh>
                <scale>1 1 1</scale>
                <uri>file:///home/fishros/MobileManipulator/workplace/install/mm_description/share/mm_description/meshes/Link_12.stl</uri>
              </mesh>
            </geometry>
            <surface>
              <contact>
                <ode/>
              </contact>
              <friction>
                <ode/>
              </friction>
            </surface>
          </collision>
          <collision name='base_link_fixed_joint_lump__Link_13_collision_3'>
            <pose>0.105689 -0.079036 0.1908 1.57079 -1.5708 0</pose>
            <geometry>
              <mesh>
                <scale>1 1 1</scale>
                <uri>file:///home/fishros/MobileManipulator/workplace/install/mm_description/share/mm_description/meshes/Link_13.stl</uri>
              </mesh>
            </geometry>
          </collision>
          <collision name='base_link_fixed_joint_lump__Link_14_collision_4'>
            <pose>0.180189 -1.3e-05 0.1908 3.14159 -1.5708 0</pose>
            <geometry>
              <mesh>
                <scale>1 1 1</scale>
                <uri>file:///home/fishros/MobileManipulator/workplace/install/mm_description/share/mm_description/meshes/Link_14.stl</uri>
              </mesh>
            </geometry>
          </collision>
          <collision name='base_link_fixed_joint_lump__Link_20_collision_5'>
            <pose>-0.029239 0.000594 0.0748 0 -0 1.57079</pose>
            <geometry>
              <mesh>
                <scale>1 1 1</scale>
                <uri>file:///home/fishros/MobileManipulator/workplace/install/mm_description/share/mm_description/meshes/Link_20.stl</uri>
              </mesh>
            </geometry>
          </collision>
          <collision name='base_link_fixed_joint_lump__base_pad_collision_6'>
            <pose>0 0 -0.0376 0 -0 0</pose>
            <geometry>
              <box>
                <size>0.03 0.03 0.02</size>
              </box>
            </geometry>
            <surface>
              <contact>
                <ode/>
              </contact>
              <friction>
                <ode>
                  <mu>1</mu>
                  <mu2>1</mu2>
                </ode>
              </friction>
            </surface>
          </collision>
          <visual name='base_link_visual'>
            <pose>0 0 0 0 -0 0</pose>
            <geometry>
              <mesh>
                <scale>1 1 1</scale>
                <uri>file:///home/fishros/MobileManipulator/workplace/install/mm_description/share/mm_description/meshes/base_link.stl</uri>
              </mesh>
            </geometry>
          </visual>
          <visual name='base_link_fixed_joint_lump__Link_11_visual_1'>
            <pose>-0.179276 0.000111 0.0758 3.14159 -1.5708 0</pose>
            <geometry>
              <mesh>
                <scale>1 1 1</scale>
                <uri>file:///home/fishros/MobileManipulator/workplace/install/mm_description/share/mm_description/meshes/Link_11.stl</uri>
              </mesh>
            </geometry>
          </visual>
          <visual name='base_link_fixed_joint_lump__Link_12_visual_2'>
            <pose>0.105689 -1.3e-05 0.2208 -3.14159 -0 -4e-06</pose>
            <geometry>
              <mesh>
                <scale>1 1 1</scale>
                <uri>file:///home/fishros/MobileManipulator/workplace/install/mm_description/share/mm_description/meshes/Link_12.stl</uri>
              </mesh>
            </geometry>
          </visual>
          <visual name='base_link_fixed_joint_lump__Link_13_visual_3'>
            <pose>0.105689 -0.079036 0.1908 1.57079 -1.5708 0</pose>
            <geometry>
              <mesh>
                <scale>1 1 1</scale>
                <uri>file:///home/fishros/MobileManipulator/workplace/install/mm_description/share/mm_description/meshes/Link_13.stl</uri>
              </mesh>
            </geometry>
          </visual>
          <visual name='base_link_fixed_joint_lump__Link_14_visual_4'>
            <pose>0.180189 -1.3e-05 0.1908 3.14159 -1.5708 0</pose>
            <geometry>
              <mesh>
                <scale>1 1 1</scale>
                <uri>file:///home/fishros/MobileManipulator/workplace/install/mm_description/share/mm_description/meshes/Link_14.stl</uri>
              </mesh>
            </geometry>
          </visual>
          <visual name='base_link_fixed_joint_lump__Link_20_visual_5'>
            <pose>-0.029239 0.000594 0.0748 0 -0 1.57079</pose>
            <geometry>
              <mesh>
                <scale>1 1 1</scale>
                <uri>file:///home/fishros/MobileManipulator/workplace/install/mm_description/share/mm_description/meshes/Link_20.stl</uri>
              </mesh>
            </geometry>
          </visual>
          <sensor name='lidar_sensor' type='ray'>
            <visualize>1</visualize>
            <update_rate>10</update_rate>
            <ray>
              <scan>
                <horizontal>
                  <samples>1200</samples>
                  <resolution>1</resolution>
                  <min_angle>-2.61799</min_angle>
                  <max_angle>2.61799</max_angle>
                </horizontal>
              </scan>
              <range>
                <min>0.12</min>
                <max>25</max>
                <resolution>0.01</resolution>
              </range>
              <noise>
                <type>gaussian</type>
                <mean>0</mean>
                <stddev>0.01</stddev>
              </noise>
            </ray>
            <plugin name='laser_plugin' filename='libgazebo_ros_ray_sensor.so'>
              <ros>
                <remapping>~/out:=scan</remapping>
              </ros>
              <output_type>sensor_msgs/LaserScan</output_type>
              <frame_name>Link_12</frame_name>
            </plugin>
            <pose>0.105689 -1.3e-05 0.2208 -3.14159 0 -4e-06</pose>
          </sensor>
        </link>
        <joint name='Joint_1' type='revolute'>
          <pose relative_to='base_link'>0.138767 0.138968 -0.00648 1.5704 -0 -0.785402</pose>
          <parent>base_link</parent>
          <child>Link_6</child>
          <axis>
            <xyz>0 0 1</xyz>
            <limit>
              <lower>-1e+16</lower>
              <upper>1e+16</upper>
            </limit>
            <dynamics>
              <spring_reference>0</spring_reference>
              <spring_stiffness>0</spring_stiffness>
            </dynamics>
          </axis>
        </joint>
        <link name='Link_6'>
          <pose relative_to='Joint_1'>0 0 0 0 -0 0</pose>
          <inertial>
            <pose>0 0 -0.011 0 -0 0</pose>
            <mass>0.241173</mass>
            <inertia>
              <ixx>0.00011077</ixx>
              <ixy>0</ixy>
              <ixz>0</ixz>
              <iyy>0.00011077</iyy>
              <iyz>0</iyz>
              <izz>0.00020208</izz>
            </inertia>
          </inertial>
          <collision name='Link_6_collision'>
            <pose>0 0 0 0 -0 0</pose>
            <geometry>
              <mesh>
                <scale>1 1 1</scale>
                <uri>file:///home/fishros/MobileManipulator/workplace/install/mm_description/share/mm_description/meshes/Link_6.stl</uri>
              </mesh>
            </geometry>
            <surface>
              <contact>
                <ode/>
              </contact>
              <friction>
                <ode>
                  <mu>0</mu>
                  <mu2>0</mu2>
                </ode>
              </friction>
            </surface>
          </collision>
          <visual name='Link_6_visual'>
            <pose>0 0 0 0 -0 0</pose>
            <geometry>
              <mesh>
                <scale>1 1 1</scale>
                <uri>file:///home/fishros/MobileManipulator/workplace/install/mm_description/share/mm_description/meshes/Link_6.stl</uri>
              </mesh>
            </geometry>
          </visual>
        </link>
        <joint name='Joint_2' type='revolute'>
          <pose relative_to='base_link'>0.138766 -0.138929 -0.006599 1.56481 0 -2.35618</pose>
          <parent>base_link</parent>
          <child>Link_7</child>
          <axis>
            <xyz>0 0 1</xyz>
            <limit>
              <lower>-1e+16</lower>
              <upper>1e+16</upper>
            </limit>
            <dynamics>
              <spring_reference>0</spring_reference>
              <spring_stiffness>0</spring_stiffness>
            </dynamics>
          </axis>
        </joint>
        <link name='Link_7'>
          <pose relative_to='Joint_2'>0 0 0 0 -0 0</pose>
          <inertial>
            <pose>0 0 -0.011 0 -0 0</pose>
            <mass>0.241173</mass>
            <inertia>
              <ixx>0.00011077</ixx>
              <ixy>0</ixy>
              <ixz>0</ixz>
              <iyy>0.00011077</iyy>
              <iyz>0</iyz>
              <izz>0.00020208</izz>
            </inertia>
          </inertial>
          <collision name='Link_7_collision'>
            <pose>0 0 0 0 -0 0</pose>
            <geometry>
              <mesh>
                <scale>1 1 1</scale>
                <uri>file:///home/fishros/MobileManipulator/workplace/install/mm_description/share/mm_description/meshes/Link_7.stl</uri>
              </mesh>
            </geometry>
            <surface>
              <contact>
                <ode/>
              </contact>
              <friction>
                <ode>
                  <mu>0</mu>
                  <mu2>0</mu2>
                </ode>
              </friction>
            </surface>
          </collision>
          <visual name='Link_7_visual'>
            <pose>0 0 0 0 -0 0</pose>
            <geometry>
              <mesh>
                <scale>1 1 1</scale>
                <uri>file:///home/fishros/MobileManipulator/workplace/install/mm_description/share/mm_description/meshes/Link_7.stl</uri>
              </mesh>
            </geometry>
          </visual>
        </link>
        <joint name='Joint_3' type='revolute'>
          <pose relative_to='base_link'>-0.138683 0.138995 -0.006599 1.56481 0 0.785412</pose>
          <parent>base_link</parent>
          <child>Link_9</child>
          <axis>
            <xyz>0 0 1</xyz>
            <limit>
              <lower>-1e+16</lower>
              <upper>1e+16</upper>
            </limit>
            <dynamics>
              <spring_reference>0</spring_reference>
              <spring_stiffness>0</spring_stiffness>
            </dynamics>
          </axis>
        </joint>
        <link name='Link_9'>
          <pose relative_to='Joint_3'>0 0 0 0 -0 0</pose>
          <inertial>
            <pose>-0 0 -0.011 0 -0 0</pose>
            <mass>0.241173</mass>
            <inertia>
              <ixx>0.00011077</ixx>
              <ixy>0</ixy>
              <ixz>0</ixz>
              <iyy>0.00011077</iyy>
              <iyz>0</iyz>
              <izz>0.00020208</izz>
            </inertia>
          </inertial>
          <collision name='Link_9_collision'>
            <pose>0 0 0 0 -0 0</pose>
            <geometry>
              <mesh>
                <scale>1 1 1</scale>
                <uri>file:///home/fishros/MobileManipulator/workplace/install/mm_description/share/mm_description/meshes/Link_9.stl</uri>
              </mesh>
            </geometry>
            <surface>
              <contact>
                <ode/>
              </contact>
              <friction>
                <ode>
                  <mu>0</mu>
                  <mu2>0</mu2>
                </ode>
              </friction>
            </surface>
          </collision>
          <visual name='Link_9_visual'>
            <pose>0 0 0 0 -0 0</pose>
            <geometry>
              <mesh>
                <scale>1 1 1</scale>
                <uri>file:///home/fishros/MobileManipulator/workplace/install/mm_description/share/mm_description/meshes/Link_9.stl</uri>
              </mesh>
            </geometry>
          </visual>
        </link>
        <joint name='Joint_4' type='revolute'>
          <pose relative_to='base_link'>-0.138684 -0.138901 -0.006481 1.5704 0 2.35619</pose>
          <parent>base_link</parent>
          <child>Link_10</child>
          <axis>
            <xyz>0 0 1</xyz>
            <limit>
              <lower>-1e+16</lower>
              <upper>1e+16</upper>
            </limit>
            <dynamics>
              <spring_reference>0</spring_reference>
              <spring_stiffness>0</spring_stiffness>
            </dynamics>
          </axis>
        </joint>
        <link name='Link_10'>
          <pose relative_to='Joint_4'>0 0 0 0 -0 0</pose>
          <inertial>
            <pose>0 0 -0.011 0 -0 0</pose>
            <mass>0.241173</mass>
            <inertia>
              <ixx>0.00011077</ixx>
              <ixy>0</ixy>
              <ixz>0</ixz>
              <iyy>0.00011077</iyy>
              <iyz>0</iyz>
              <izz>0.00020208</izz>
            </inertia>
          </inertial>
          <collision name='Link_10_collision'>
            <pose>0 0 0 0 -0 0</pose>
            <geometry>
              <mesh>
                <scale>1 1 1</scale>
                <uri>file:///home/fishros/MobileManipulator/workplace/install/mm_description/share/mm_description/meshes/Link_10.stl</uri>
              </mesh>
            </geometry>
            <surface>
              <contact>
                <ode/>
              </contact>
              <friction>
                <ode>
                  <mu>0</mu>
                  <mu2>0</mu2>
                </ode>
              </friction>
            </surface>
          </collision>
          <visual name='Link_10_visual'>
            <pose>0 0 0 0 -0 0</pose>
            <geometry>
              <mesh>
                <scale>1 1 1</scale>
                <uri>file:///home/fishros/MobileManipulator/workplace/install/mm_description/share/mm_description/meshes/Link_10.stl</uri>
              </mesh>
            </geometry>
          </visual>
        </link>
        <joint name='Joint_11' type='revolute'>
          <pose relative_to='base_link'>-0.029239 0.000594 0.1722 0 0 -0.811582</pose>
          <parent>base_link</parent>
          <child>Link_21</child>
          <axis>
            <xyz>0 0 -1</xyz>
            <limit>
              <lower>0</lower>
              <upper>4.712</upper>
              <effort>10</effort>
              <velocity>1</velocity>
            </limit>
            <dynamics>
              <spring_reference>0</spring_reference>
              <spring_stiffness>0</spring_stiffness>
            </dynamics>
          </axis>
        </joint>
        <link name='Link_21'>
          <pose relative_to='Joint_11'>0 0 0 0 -0 0</pose>
          <inertial>
            <pose>-0.000234 -0.00135 0.03671 0 -0 0</pose>
            <mass>0.289347</mass>
            <inertia>
              <ixx>0.00024118</ixx>
              <ixy>1.6e-07</ixy>
              <ixz>-9e-07</ixz>
              <iyy>0.00018977</iyy>
              <iyz>-1.324e-05</iyz>
              <izz>0.0001893</izz>
            </inertia>
          </inertial>
          <collision name='Link_21_collision'>
            <pose>0 0 0 0 -0 0</pose>
            <geometry>
              <mesh>
                <scale>1 1 1</scale>
                <uri>file:///home/fishros/MobileManipulator/workplace/install/mm_description/share/mm_description/meshes/Link_21.stl</uri>
              </mesh>
            </geometry>
          </collision>
          <visual name='Link_21_visual'>
            <pose>0 0 0 0 -0 0</pose>
            <geometry>
              <mesh>
                <scale>1 1 1</scale>
                <uri>file:///home/fishros/MobileManipulator/workplace/install/mm_description/share/mm_description/meshes/Link_21.stl</uri>
              </mesh>
            </geometry>
          </visual>
        </link>
        <joint name='Joint_12' type='revolute'>
          <pose relative_to='Link_21'>0 -0.0514 0.0473 1.5708 1.16937 -3.14159</pose>
          <parent>Link_21</parent>
          <child>Link_22</child>
          <axis>
            <xyz>0 0 1</xyz>
            <limit>
              <lower>0</lower>
              <upper>2.74</upper>
              <effort>10</effort>
              <velocity>1</velocity>
            </limit>
            <dynamics>
              <spring_reference>0</spring_reference>
              <spring_stiffness>0</spring_stiffness>
            </dynamics>
          </axis>
        </joint>
        <link name='Link_22'>
          <pose relative_to='Joint_12'>0 0 0 0 -0 0</pose>
          <inertial>
            <pose>-7.7e-05 0.105274 0.007491 0 -0 0</pose>
            <mass>0.418274</mass>
            <inertia>
              <ixx>0.00251557</ixx>
              <ixy>3.98e-06</ixy>
              <ixz>1e-06</ixz>
              <iyy>0.00021564</iyy>
              <iyz>9.753e-05</iyz>
              <izz>0.00253221</izz>
            </inertia>
          </inertial>
          <collision name='Link_22_collision'>
            <pose>0 0 0 0 -0 0</pose>
            <geometry>
              <mesh>
                <scale>1 1 1</scale>
                <uri>file:///home/fishros/MobileManipulator/workplace/install/mm_description/share/mm_description/meshes/Link_22.stl</uri>
              </mesh>
            </geometry>
          </collision>
          <visual name='Link_22_visual'>
            <pose>0 0 0 0 -0 0</pose>
            <geometry>
              <mesh>
                <scale>1 1 1</scale>
                <uri>file:///home/fishros/MobileManipulator/workplace/install/mm_description/share/mm_description/meshes/Link_22.stl</uri>
              </mesh>
            </geometry>
          </visual>
        </link>
        <joint name='Joint_13' type='revolute'>
          <pose relative_to='Link_22'>0 0.2125 0.0224 3.14159 -0 -2.58309</pose>
          <parent>Link_22</parent>
          <child>Link_23</child>
          <axis>
            <xyz>0 0 1</xyz>
            <limit>
              <lower>0</lower>
              <upper>2.304</upper>
              <effort>10</effort>
              <velocity>1</velocity>
            </limit>
            <dynamics>
              <spring_reference>0</spring_reference>
              <spring_stiffness>0</spring_stiffness>
            </dynamics>
          </axis>
        </joint>
        <link name='Link_23'>
          <pose relative_to='Joint_13'>0 0 0 0 -0 0</pose>
          <inertial>
            <pose>0.013157 -0.027972 -0.036809 0 -0 0</pose>
            <mass>0.339777</mass>
            <inertia>
              <ixx>0.00027686</ixx>
              <ixy>-5.481e-05</ixy>
              <ixz>2.44e-06</ixz>
              <iyy>0.00026916</iyy>
              <iyz>-2.01e-05</iyz>
              <izz>0.00040556</izz>
            </inertia>
          </inertial>
          <collision name='Link_23_collision'>
            <pose>0 0 0 0 -0 0</pose>
            <geometry>
              <mesh>
                <scale>1 1 1</scale>
                <uri>file:///home/fishros/MobileManipulator/workplace/install/mm_description/share/mm_description/meshes/Link_23.stl</uri>
              </mesh>
            </geometry>
          </collision>
          <visual name='Link_23_visual'>
            <pose>0 0 0 0 -0 0</pose>
            <geometry>
              <mesh>
                <scale>1 1 1</scale>
                <uri>file:///home/fishros/MobileManipulator/workplace/install/mm_description/share/mm_description/meshes/Link_23.stl</uri>
              </mesh>
            </geometry>
          </visual>
        </link>
        <joint name='Joint_14' type='revolute'>
          <pose relative_to='Link_23'>0.06779 0 -0.040208 1.56207 0 -1.5708</pose>
          <parent>Link_23</parent>
          <child>Link_24</child>
          <axis>
            <xyz>0 0 1</xyz>
            <limit>
              <lower>0</lower>
              <upper>3.142</upper>
              <effort>10</effort>
              <velocity>1</velocity>
            </limit>
            <dynamics>
              <spring_reference>0</spring_reference>
              <spring_stiffness>0</spring_stiffness>
            </dynamics>
          </axis>
        </joint>
        <link name='Link_24'>
          <pose relative_to='Joint_14'>0 0 0 0 -0 0</pose>
          <inertial>
            <pose>-7.7e-05 -1e-05 0.011665 0 -0 0</pose>
            <mass>0.414886</mass>
            <inertia>
              <ixx>0.00337314</ixx>
              <ixy>-3e-07</ixy>
              <ixz>-1.687e-05</ixz>
              <iyy>0.00340699</iyy>
              <iyz>4.1e-07</iyz>
              <izz>0.000143</izz>
            </inertia>
          </inertial>
          <collision name='Link_24_collision'>
            <pose>0 0 0 0 -0 0</pose>
            <geometry>
              <mesh>
                <scale>1 1 1</scale>
                <uri>file:///home/fishros/MobileManipulator/workplace/install/mm_description/share/mm_description/meshes/Link_24.stl</uri>
              </mesh>
            </geometry>
          </collision>
          <visual name='Link_24_visual'>
            <pose>0 0 0 0 -0 0</pose>
            <geometry>
              <mesh>
                <scale>1 1 1</scale>
                <uri>file:///home/fishros/MobileManipulator/workplace/install/mm_description/share/mm_description/meshes/Link_24.stl</uri>
              </mesh>
            </geometry>
          </visual>
        </link>
        <joint name='Joint_15' type='revolute'>
          <pose relative_to='Link_24'>-0.0252 0 -0.1316 0 -1.5708 0</pose>
          <parent>Link_24</parent>
          <child>Link_25</child>
          <axis>
            <xyz>0 0 -1</xyz>
            <limit>
              <lower>-1.571</lower>
              <upper>1.571</upper>
              <effort>10</effort>
              <velocity>1</velocity>
            </limit>
            <dynamics>
              <spring_reference>0</spring_reference>
              <spring_stiffness>0</spring_stiffness>
            </dynamics>
          </axis>
        </joint>
        <link name='Link_25'>
          <pose relative_to='Joint_15'>0 0 0 0 -0 0</pose>
          <inertial>
            <pose>-0.004904 -0.006773 -0.025788 0 -0 0</pose>
            <mass>0.0554399</mass>
            <inertia>
              <ixx>2.782e-05</ixx>
              <ixy>-2.32e-06</ixy>
              <ixz>6.9e-07</ixz>
              <iyy>1.842e-05</iyy>
              <iyz>1.24e-06</iyz>
              <izz>2.306e-05</izz>
            </inertia>
          </inertial>
          <collision name='Link_25_collision'>
            <pose>0 0 0 0 -0 0</pose>
            <geometry>
              <mesh>
                <scale>1 1 1</scale>
                <uri>file:///home/fishros/MobileManipulator/workplace/install/mm_description/share/mm_description/meshes/Link_25.stl</uri>
              </mesh>
            </geometry>
          </collision>
          <visual name='Link_25_visual'>
            <pose>0 0 0 0 -0 0</pose>
            <geometry>
              <mesh>
                <scale>1 1 1</scale>
                <uri>file:///home/fishros/MobileManipulator/workplace/install/mm_description/share/mm_description/meshes/Link_25.stl</uri>
              </mesh>
            </geometry>
          </visual>
        </link>
        <joint name='Joint_16' type='revolute'>
          <pose relative_to='Link_25'>0 -0.046 -0.0251 1.5708 0.008728 3.14159</pose>
          <parent>Link_25</parent>
          <child>Link_29</child>
          <axis>
            <xyz>0 0 1</xyz>
            <limit>
              <lower>-1.571</lower>
              <upper>1.571</upper>
              <effort>10</effort>
              <velocity>1</velocity>
            </limit>
            <dynamics>
              <spring_reference>0</spring_reference>
              <spring_stiffness>0</spring_stiffness>
            </dynamics>
          </axis>
        </joint>
        <link name='Link_29'>
          <pose relative_to='Joint_16'>0 0 0 0 -0 0</pose>
          <inertial>
            <pose>0.024945 0.00052 -0.025926 0 -0 0</pose>
            <mass>0.199472</mass>
            <inertia>
              <ixx>0.00013444</ixx>
              <ixy>-1.88047e-06</ixy>
              <ixz>-1.69707e-05</ixz>
              <iyy>0.000166922</iyy>
              <iyz>-8.78761e-07</iyz>
              <izz>0.000168313</izz>
            </inertia>
          </inertial>
          <collision name='Link_29_collision'>
            <pose>0 0 0 0 -0 0</pose>
            <geometry>
              <mesh>
                <scale>1 1 1</scale>
                <uri>file:///home/fishros/MobileManipulator/workplace/install/mm_description/share/mm_description/meshes/Link_29.stl</uri>
              </mesh>
            </geometry>
          </collision>
          <collision name='Link_29_fixed_joint_lump__Link_30_collision_1'>
            <pose>0.055379 0.00725 -0.01913 1.5708 1.5708 0</pose>
            <geometry>
              <mesh>
                <scale>1 1 1</scale>
                <uri>file:///home/fishros/MobileManipulator/workplace/install/mm_description/share/mm_description/meshes/Link_30.stl</uri>
              </mesh>
            </geometry>
          </collision>
          <visual name='Link_29_visual'>
            <pose>0 0 0 0 -0 0</pose>
            <geometry>
              <mesh>
                <scale>1 1 1</scale>
                <uri>file:///home/fishros/MobileManipulator/workplace/install/mm_description/share/mm_description/meshes/Link_29.stl</uri>
              </mesh>
            </geometry>
          </visual>
          <visual name='Link_29_fixed_joint_lump__Link_30_visual_1'>
            <pose>0.055379 0.00725 -0.01913 1.5708 1.5708 0</pose>
            <geometry>
              <mesh>
                <scale>1 1 1</scale>
                <uri>file:///home/fishros/MobileManipulator/workplace/install/mm_description/share/mm_description/meshes/Link_30.stl</uri>
              </mesh>
            </geometry>
          </visual>
        </link>
        <plugin name='gazebo_ros2_control' filename='libgazebo_ros2_control.so'>
          <parameters>/home/fishros/MobileManipulator/workplace/install/arm_moveit_config/share/arm_moveit_config/config/ros2_controllers.yaml</parameters>
        </plugin>
        <static>0</static>
        <plugin name='object_controller' filename='libgazebo_ros_planar_move.so'>
          <ros>
            <remapping>cmd_vel:=cmd_vel_smoothed</remapping>
          </ros>
          <odometry_frame>odom</odometry_frame>
          <robot_base_frame>base_link</robot_base_frame>
          <odometry_rate>50.0</odometry_rate>
          <publish_odom>1</publish_odom>
          <publish_odom_tf>1</publish_odom_tf>
        </plugin>
      </model>
  </world>
</sdf>
