<?xml version="1.0" encoding="UTF-8"?>
<robot name="arm_description">
  <link name="base_link">
    <inertial>
      <mass value="7.14872571"/>
      <origin xyz="0.00031207 0.03211671 0.03073628" rpy="0 0 0"/>
      <inertia ixx="0.04607342" ixy="-0.00002464" ixz="-0.00008105" iyy="0.02469195" iyz="-0.00061321" izz="0.06493327"/>
    </inertial>
    <visual>
      <origin xyz="0 0 0" rpy="0 0 0"/>
      <geometry>
        <mesh filename="package://arm_description/meshes/base_link.stl"/>
      </geometry>
    </visual>
    <collision>
      <origin xyz="0 0 0" rpy="0 0 0"/>
      <geometry>
        <mesh filename="package://arm_description/meshes/base_link.stl"/>
      </geometry>
    </collision>
  </link>
  <link name="Link_1">
    <inertial>
      <mass value="0.57848047"/>
      <origin xyz="0.00123363 -0.00021385 0.05305743" rpy="0 0 0"/>
      <inertia ixx="0.00051134" ixy="-3.3e-7" ixz="0.00002033" iyy="0.00060483" iyz="-0.00000102" izz="0.00036384"/>
    </inertial>
    <visual>
      <origin xyz="0 0 0" rpy="0 0 0"/>
      <geometry>
        <mesh filename="package://arm_description/meshes/Link_1.stl"/>
      </geometry>
    </visual>
    <collision>
      <origin xyz="0 0 0" rpy="0 0 0"/>
      <geometry>
        <mesh filename="package://arm_description/meshes/Link_1.stl"/>
      </geometry>
    </collision>
  </link>
  <link name="Link_2">
    <inertial>
      <mass value="0.76000701"/>
      <origin xyz="-0.1077907 0.0000766 -0.01149107" rpy="0 0 0"/>
      <inertia ixx="0.00039175" ixy="0.00000721" ixz="0.00017714" iyy="0.00457239" iyz="0.00000183" izz="0.00460255"/>
    </inertial>
    <visual>
      <origin xyz="0 0 0" rpy="0 0 0"/>
      <geometry>
        <mesh filename="package://arm_description/meshes/Link_2.stl"/>
      </geometry>
    </visual>
    <collision>
      <origin xyz="0 0 0" rpy="0 0 0"/>
      <geometry>
        <mesh filename="package://arm_description/meshes/Link_2.stl"/>
      </geometry>
    </collision>
  </link>
  <link name="Link_3">
    <inertial>
      <mass value="0.61846202"/>
      <origin xyz="0.02806316 0.01315082 -0.0367866" rpy="0 0 0"/>
      <inertia ixx="0.0004893" ixy="0.00009982" ixz="0.00003613" iyy="0.00051115" iyz="0.00000453" izz="0.00074479"/>
    </inertial>
    <visual>
      <origin xyz="0 0 0" rpy="0 0 0"/>
      <geometry>
        <mesh filename="package://arm_description/meshes/Link_3.stl"/>
      </geometry>
    </visual>
    <collision>
      <origin xyz="0 0 0" rpy="0 0 0"/>
      <geometry>
        <mesh filename="package://arm_description/meshes/Link_3.stl"/>
      </geometry>
    </collision>
  </link>
  <link name="Link_4">
    <inertial>
      <mass value="0.75422379"/>
      <origin xyz="0.00007716 -0.00001007 0.0073403" rpy="0 0 0"/>
      <inertia ixx="0.00613059" ixy="5.4e-7" ixz="-0.00003068" iyy="0.00619208" iyz="-7.2e-7" izz="0.00025988"/>
    </inertial>
    <visual>
      <origin xyz="0 0 0" rpy="0 0 0"/>
      <geometry>
        <mesh filename="package://arm_description/meshes/Link_4.stl"/>
      </geometry>
    </visual>
    <collision>
      <origin xyz="0 0 0" rpy="0 0 0"/>
      <geometry>
        <mesh filename="package://arm_description/meshes/Link_4.stl"/>
      </geometry>
    </collision>
  </link>
  <link name="Link_5">
    <inertial>
      <mass value="0.10076769"/>
      <origin xyz="0.00490907 -0.00678848 -0.03041582" rpy="0 0 0"/>
      <inertia ixx="0.00005054" ixy="0.00000421" ixz="0.00000125" iyy="0.00003343" iyz="-0.00000225" izz="0.0000419"/>
    </inertial>
    <visual>
      <origin xyz="0 0 0" rpy="0 0 0"/>
      <geometry>
        <mesh filename="package://arm_description/meshes/Link_5.stl"/>
      </geometry>
    </visual>
    <collision>
      <origin xyz="0 0 0" rpy="0 0 0"/>
      <geometry>
        <mesh filename="package://arm_description/meshes/Link_5.stl"/>
      </geometry>
    </collision>
  </link>
  <link name="Link_6">
    <inertial>
      <mass value="0.03933331"/>
      <origin xyz="0.00002461 -0.00023702 0.01991533" rpy="0 0 0"/>
      <inertia ixx="0.00000484" ixy="5e-8" ixz="2e-8" iyy="0.00001166" iyz="-7e-8" izz="0.00000922"/>
    </inertial>
    <visual>
      <origin xyz="0 0 0" rpy="0 0 0"/>
      <geometry>
        <mesh filename="package://arm_description/meshes/Link_6.stl"/>
      </geometry>
    </visual>
    <collision>
      <origin xyz="0 0 0" rpy="0 0 0"/>
      <geometry>
        <mesh filename="package://arm_description/meshes/Link_6.stl"/>
      </geometry>
    </collision>
  </link>
  <joint name="Joint_1" type="revolute">
    <parent link="base_link"/>
    <child link="Link_1"/>
    <origin xyz="-0.00003461 0.04262805 0.07986836" rpy="0 0 2.33001455"/>
    <axis xyz="0 0 -1"/>
    <limit lower="0" upper="4.712" effort="10" velocity="1"/>
  </joint>
  <joint name="Joint_2" type="revolute">
    <parent link="Link_1"/>
    <child link="Link_2"/>
    <origin xyz="0.0554 0 0.0663" rpy="1.57079633 0.40142573 1.57079633"/>
    <axis xyz="0 0 -1"/>
    <limit lower="0" upper="2.740" effort="10" velocity="1"/>
  </joint>
  <joint name="Joint_3" type="revolute">
    <parent link="Link_2"/>
    <child link="Link_3"/>
    <origin xyz="-0.21500002 0 -0.0264" rpy="0 0 -0.55850536"/>
    <axis xyz="0 0 1"/>
    <limit lower="0" upper="2.304" effort="10" velocity="1"/>
  </joint>
  <joint name="Joint_4" type="revolute">
    <parent link="Link_3"/>
    <child link="Link_4"/>
    <origin xyz="0 0.04879037 -0.04004253" rpy="1.57952416 0.00000000 3.14159265"/>
    <axis xyz="0 0 -1"/>
    <limit lower="0" upper="3.142" effort="10" velocity="1"/>
  </joint>
  <joint name="Joint_5" type="revolute">
    <parent link="Link_4"/>
    <child link="Link_5"/>
    <origin xyz="-0.03100018 0 0.15059996" rpy="0 -1.57079633 0"/>
    <axis xyz="0 0 1"/>
    <limit lower="-1.571" upper="1.571" effort="10" velocity="1"/>
  </joint>
  <joint name="Joint_6" type="revolute">
    <parent link="Link_5"/>
    <child link="Link_6"/>
    <origin xyz="3e-8 -0.033 -0.0311" rpy="1.57079633 1.56206849 0"/>
    <axis xyz="0 0 1"/>
    <limit lower="-1.571" upper="1.571" effort="10" velocity="1"/>
  </joint>
</robot>
